2018-12-18 11:55:25,262 ERROR: Exception on /explore [GET] [in /Users/anthonychen/Documents/practice/Flask/venv/lib/python3.7/site-packages/flask/app.py:1761]
Traceback (most recent call last):
  File "/Users/anthonychen/Documents/practice/Flask/venv/lib/python3.7/site-packages/flask/app.py", line 2292, in wsgi_app
    response = self.full_dispatch_request()
  File "/Users/anthonychen/Documents/practice/Flask/venv/lib/python3.7/site-packages/flask/app.py", line 1815, in full_dispatch_request
    rv = self.handle_user_exception(e)
  File "/Users/anthonychen/Documents/practice/Flask/venv/lib/python3.7/site-packages/flask/app.py", line 1718, in handle_user_exception
    reraise(exc_type, exc_value, tb)
  File "/Users/anthonychen/Documents/practice/Flask/venv/lib/python3.7/site-packages/flask/_compat.py", line 35, in reraise
    raise value
  File "/Users/anthonychen/Documents/practice/Flask/venv/lib/python3.7/site-packages/flask/app.py", line 1813, in full_dispatch_request
    rv = self.dispatch_request()
  File "/Users/anthonychen/Documents/practice/Flask/venv/lib/python3.7/site-packages/flask/app.py", line 1799, in dispatch_request
    return self.view_functions[rule.endpoint](**req.view_args)
  File "/Users/anthonychen/Documents/practice/Flask/venv/lib/python3.7/site-packages/flask_login/utils.py", line 261, in decorated_view
    return func(*args, **kwargs)
  File "/Users/anthonychen/Documents/practice/Flask/app/routes.py", line 141, in explore
    return render_template('index.html', title = 'Explore', posts=posts.items, next_url = next_url, prev_url = prev_url)
  File "/Users/anthonychen/Documents/practice/Flask/venv/lib/python3.7/site-packages/flask/templating.py", line 135, in render_template
    context, ctx.app)
  File "/Users/anthonychen/Documents/practice/Flask/venv/lib/python3.7/site-packages/flask/templating.py", line 117, in _render
    rv = template.render(context)
  File "/Users/anthonychen/Documents/practice/Flask/venv/lib/python3.7/site-packages/jinja2/asyncsupport.py", line 76, in render
    return original_render(self, *args, **kwargs)
  File "/Users/anthonychen/Documents/practice/Flask/venv/lib/python3.7/site-packages/jinja2/environment.py", line 1008, in render
    return self.environment.handle_exception(exc_info, True)
  File "/Users/anthonychen/Documents/practice/Flask/venv/lib/python3.7/site-packages/jinja2/environment.py", line 780, in handle_exception
    reraise(exc_type, exc_value, tb)
  File "/Users/anthonychen/Documents/practice/Flask/venv/lib/python3.7/site-packages/jinja2/_compat.py", line 37, in reraise
    raise value.with_traceback(tb)
  File "/Users/anthonychen/Documents/practice/Flask/app/templates/index.html", line 2, in top-level template code
    {% import 'bootstrap/wtf.html' as wtf %}
  File "/Users/anthonychen/Documents/practice/Flask/app/templates/base.html", line 1, in top-level template code
    {% extends 'bootstrap/base.html' %}
  File "/Users/anthonychen/Documents/practice/Flask/venv/lib/python3.7/site-packages/flask_bootstrap/templates/bootstrap/base.html", line 1, in top-level template code
    {% block doc -%}
  File "/Users/anthonychen/Documents/practice/Flask/venv/lib/python3.7/site-packages/flask_bootstrap/templates/bootstrap/base.html", line 4, in block "doc"
    {%- block html %}
  File "/Users/anthonychen/Documents/practice/Flask/venv/lib/python3.7/site-packages/flask_bootstrap/templates/bootstrap/base.html", line 20, in block "html"
    {% block body -%}
  File "/Users/anthonychen/Documents/practice/Flask/venv/lib/python3.7/site-packages/flask_bootstrap/templates/bootstrap/base.html", line 23, in block "body"
    {% block content -%}
  File "/Users/anthonychen/Documents/practice/Flask/app/templates/base.html", line 48, in block "content"
    {% block app_content %}{% endblock %}
  File "/Users/anthonychen/Documents/practice/Flask/app/templates/index.html", line 10, in block "app_content"
    {% include '_post.html'%}
  File "/Users/anthonychen/Documents/practice/Flask/app/templates/_post.html", line 12, in top-level template code
    said {{ moment(post.timestamp.fromNow()) }}:
jinja2.exceptions.UndefinedError: 'datetime.datetime object' has no attribute 'fromNow'
2018-12-18 11:56:23,897 INFO: Microblog startup [in /Users/anthonychen/Documents/practice/Flask/app/__init__.py:56]
2018-12-19 17:24:00,902 INFO: Microblog startup [in /Users/anthonychen/Documents/practice/Flask/app/__init__.py:56]
2018-12-19 17:24:08,129 INFO: Microblog startup [in /Users/anthonychen/Documents/practice/Flask/app/__init__.py:56]
2018-12-19 17:24:08,249 INFO: Microblog startup [in /Users/anthonychen/Documents/practice/Flask/app/__init__.py:56]
2018-12-19 17:24:08,253 INFO: Microblog startup [in /Users/anthonychen/Documents/practice/Flask/app/__init__.py:56]
2018-12-19 17:24:08,321 INFO: Microblog startup [in /Users/anthonychen/Documents/practice/Flask/app/__init__.py:56]
